Workbook

Sheet Bank Balance Sheet
A1: Year | B1: Month | C1: Date | D1: Previous Balance | E1: Total Withdrawals | F1: Total deposits | G1: Current Balance | H1: Column1 | I1: Profit | J1: checking
A2: 2020 | B2: October | C2: 44105 | D2: 0 | E2: 5 | F2: 1200 | G2: 1195 | I2: =F2-E2 -> 1195 | J2: =D2+I2 -> 1195 | M2: 44135
A3: 2020 | B3: November | C3: 44136 | D3: 1195 | E3: 8221.45 | F3: 45500.14 | G3: 38473.69 | I3: =F3-E3 -> 37278.69 | J3: =D3+I3 -> 38473.69
A4: 2020 | B4: December | C4: 44166 | D4: 38473.69 | E4: 0 | F4: 0.33 | G4: 38474.02 | I4: =F4-E4 -> 0.33 | J4: =D4+I4 -> 38474.02
A5: 2021 | B5: January | C5: 44197 | D5: 38474.02 | E5: 25897 | F5: 0.22 | G5: 12577.24 | I5: =F5-E5 -> -25896.78 | J5: =D5+I5 -> 12577.24
A6: 2021 | B6: February | C6: 44228 | D6: 12577.24 | E6: 8923.75 | F6: 1700.08 | G6: 5353.57 | I6: =F6-E6 -> -7223.67 | J6: =D6+I6 -> 5353.57
A7: 2021 | B7: March | C7: 44256 | D7: 5353.57 | E7: 4265 | F7: 2992.01 | G7: 4080.58 | I7: =F7-E7 -> -1272.99 | J7: =D7+I7 -> 4080.58
A8: 2021 | B8: April | C8: 44287 | D8: 4080.58 | E8: 7705.61 | F8: 6694.04 | G8: 3069.01 | I8: =F8-E8 -> -1011.57 | J8: =D8+I8 -> 3069.01
A9: 2021 | B9: May | C9: 44317 | D9: 3069.01 | E9: 11020.15 | F9: 15635.06 | G9: 7683.92 | I9: =F9-E9 -> 4614.91 | J9: =D9+I9 -> 7683.92
A10: 2021 | B10: June | C10: 44348 | D10: 7683.92 | E10: 4763.66 | F10: 6820.08 | G10: 9740.34 | I10: =F10-E10 -> 2056.42 | J10: =D10+I10 -> 9740.34
A11: 2021 | B11: July | C11: 44378 | D11: 9740.34 | E11: 21930.25 | F11: 29401.12 | G11: 17211.21 | I11: =F11-E11 -> 7470.87 | J11: =D11+I11 -> 17211.21
A12: 2021 | B12: August | C12: 44409 | D12: 17211.21 | E12: 9989.91 | F12: 3462.11 | G12: 10683.41 | I12: =F12-E12 -> -6527.8 | J12: =D12+I12 -> 10683.41
A13: 2021 | B13: September | C13: 44440 | D13: 10683.41 | E13: 121.28 | F13: 2729.1 | G13: 13291.23 | I13: =F13-E13 -> 2607.82 | J13: =D13+I13 -> 13291.23
A14: 2021 | B14: October | C14: 44470 | D14: 13291.23 | E14: 2710.83 | F14: 2933.1 | G14: 13513.5 | I14: =F14-E14 -> 222.27 | J14: =D14+I14 -> 13513.5
... A47: 2024 | B47: July | C47: 45474 | D47: 0 | E47: 0 | F47: 0 | G47: 0 | I47: =F47-E47 -> 0 | J47: =D47+I47 -> 0

Sheet Q2 Branch Comparison
B1: Quarter 2 YTD Branch Comparison
D2: Tungku | E2: Salar | F2: Bengkurong | G2: Tutong | H2: Lambak | I2: YTD
C3: Revenue | D3: =Tungku!G3+Tungku!H3+Tungku!I3 -> 31071.69 | E3: =Salar!G3+Salar!H3+Salar!I3 -> 15024.48 | F3: =Bengkurong!G3+Bengkurong!H3+Bengkurong!I3 -> 18170.01 | G3: =Tutong!G3+Tutong!H3+Tutong!I3 -> 13176.74 | H3: =Lambak!G3+Lambak!H3+Lambak!I3 -> 7487 | I3: =SUM(D3:H3) -> 84929.92
B4: Cost of Services | C4: Water Bill | D4: =Tungku!G4+Tungku!H4+Tungku!I4 -> 600 | E4: =Salar!G4+Salar!H4+Salar!I4 -> 300 | F4: =Bengkurong!G4+Bengkurong!H4+Bengkurong!I4 -> 250 | G4: =Tutong!G4+Tutong!H4+Tutong!I4 -> 200 | H4: =Lambak!G4+Lambak!H4+Lambak!I4 -> 0 | I4: =SUM(D4:H4) -> 1350
C5: Electricity Bill | D5: =Tungku!G5+Tungku!H5+Tungku!I5 -> 420 | E5: =Salar!G5+Salar!H5+Salar!I5 -> 230 | F5: =Bengkurong!G5+Bengkurong!H5+Bengkurong!I5 -> 300 | G5: =Tutong!G5+Tutong!H5+Tutong!I5 -> 280 | H5: =Lambak!G5+Lambak!H5+Lambak!I5 -> 340 | I5: =SUM(D5:H5) -> 1570
C6: Car Wash Shampoo & Tyre Shine + Car Wax | D6: =Tungku!G6+Tungku!H6+Tungku!I6 -> 1249.2 | E6: =Salar!G6+Salar!H6+Salar!I6 -> 955.3 | F6: =Bengkurong!G6+Bengkurong!H6+Bengkurong!I6 -> 908.4 | G6: =Tutong!G6+Tutong!H6+Tutong!I6 -> 1027.6 | H6: =Lambak!G6+Lambak!H6+Lambak!I6 -> 717.4 | I6: =SUM(D6:H6) -> 4857.9
C7: Staff Wages | D7: =Tungku!G7+Tungku!H7+Tungku!I7 -> 10055.81 | E7: =Salar!G7+Salar!H7+Salar!I7 -> 3766.78 | F7: =Bengkurong!G7+Bengkurong!H7+Bengkurong!I7 -> 6126.27 | G7: =Tutong!G7+Tutong!H7+Tutong!I7 -> 6609.55 | H7: =Lambak!G7+Lambak!H7+Lambak!I7 -> 4550.6 | I7: =SUM(D7:H7) -> 31109.01
C8: Part-timer Wages | D8: =Tungku!G8+Tungku!H8+Tungku!I8 -> 2233 | E8: =Salar!G8+Salar!H8+Salar!I8 -> 2949 | F8: =Bengkurong!G8+Bengkurong!H8+Bengkurong!I8 -> 79 | G8: =Tutong!G8+Tutong!H8+Tutong!I8 -> 331 | H8: =Lambak!G8+Lambak!H8+Lambak!I8 -> 746.7 | I8: =SUM(D8:H8) -> 6338.7
C9: Bonus | D9: =Tungku!G9+Tungku!H9+Tungku!I9 -> 0 | E9: =Salar!G9+Salar!H9+Salar!I9 -> 5 | F9: =Bengkurong!G9+Bengkurong!H9+Bengkurong!I9 -> 0 | G9: =Tutong!G9+Tutong!H9+Tutong!I9 -> 0 | H9: =Lambak!G9+Lambak!H9+Lambak!I9 -> 0 | I9: =SUM(D9:H9) -> 5
C10: Miscellaneous | D10: =Tungku!G10+Tungku!H10+Tungku!I10 -> 1091.54 | E10: =Salar!G10+Salar!H10+Salar!I10 -> 14.48 | F10: =Bengkurong!G10+Bengkurong!H10+Bengkurong!I10 -> 0 | G10: =Tutong!G10+Tutong!H10+Tutong!I10 -> 0 | H10: =Lambak!G10+Lambak!H10+Lambak!I10 -> 500 | I10: =SUM(D10:H10) -> 1606.02
C11: Maintenance & Repair | D11: =Tungku!G11+Tungku!H11+Tungku!I11 -> 479.4 | E11: =Salar!G11+Salar!H11+Salar!I11 -> 0 | F11: =Bengkurong!G11+Bengkurong!H11+Bengkurong!I11 -> 51 | G11: =Tutong!G11+Tutong!H11+Tutong!I11 -> 0 | H11: =Lambak!G11+Lambak!H11+Lambak!I11 -> 0 | I11: =SUM(D11:H11) -> 530.4
C12: Total COS | D12: =SUM(D4:D11) -> 16128.95 | E12: =SUM(E4:E11) -> 8220.56 | F12: =SUM(F4:F11) -> 7714.67 | G12: =SUM(G4:G11) -> 8448.15 | H12: =SUM(H4:H11) -> 6854.7 | I12: =SUM(D12:H12) -> 47367.03
C13: Gross Profit | D13: =Tungku!G13+Tungku!H13+Tungku!I13 -> 14942.74 | E13: =Salar!G13+Salar!H13+Salar!I13 -> 6803.92 | F13: =Bengkurong!G13+Bengkurong!H13+Bengkurong!I13 -> 10455.34 | G13: =Tutong!G13+Tutong!H13+Tutong!I13 -> 4728.59 | H13: =Lambak!G13+Lambak!H13+Lambak!I13 -> 632.3 | I13: =SUM(D13:H13) -> 37562.89
B14: Operating Expense | C14: Total Units Rental | D14: =Tungku!G14+Tungku!H14+Tungku!I14 -> 9900 | E14: =Salar!G14+Salar!H14+Salar!I14 -> 6600 | F14: =Bengkurong!G14+Bengkurong!H14+Bengkurong!I14 -> 3000 | G14: =Tutong!G14+Tutong!H14+Tutong!I14 -> 1950 | H14: =Lambak!G14+Lambak!H14+Lambak!I14 -> 3000 | I14: =SUM(D14:H14) -> 24450
C15: Point-of-Sale System | D15: =Tungku!G15+Tungku!H15+Tungku!I15 -> 60 | E15: =Salar!G15+Salar!H15+Salar!I15 -> 60 | F15: =Bengkurong!G15+Bengkurong!H15+Bengkurong!I15 -> 60 | G15: =Tutong!G15+Tutong!H15+Tutong!I15 -> 60 | H15: =Lambak!G15+Lambak!H15+Lambak!I15 -> 60 | I15: =SUM(D15:H15) -> 300
C16: Wifi Internet | D16: =Tungku!G16+Tungku!H16+Tungku!I16 -> 174 | E16: =Salar!G16+Salar!H16+Salar!I16 -> 114 | F16: =Bengkurong!G16+Bengkurong!H16+Bengkurong!I16 -> 114 | G16: =Tutong!G16+Tutong!H16+Tutong!I16 -> 114 | H16: =Lambak!G16+Lambak!H16+Lambak!I16 -> 119 | I16: =SUM(D16:H16) -> 635
C17: SPK | D17: =Tungku!G17+Tungku!H17+Tungku!I17 -> 806.26 | E17: =Salar!G17+Salar!H17+Salar!I17 -> 345.54 | F17: =Bengkurong!G17+Bengkurong!H17+Bengkurong!I17 -> 518.31 | G17: =Tutong!G17+Tutong!H17+Tutong!I17 -> 691.08 | H17: =Lambak!G17+Lambak!H17+Lambak!I17 -> 172.69 | I17: =SUM(D17:H17) -> 2533.88
C18: Connecteam (Employmee Management App) | D18: =Tungku!G18+Tungku!H18+Tungku!I18 -> 166.39 | E18: =Salar!G18+Salar!H18+Salar!I18 -> 166.39 | F18: =Bengkurong!G18+Bengkurong!H18+Bengkurong!I18 -> 166.39 | G18: =Tutong!G18+Tutong!H18+Tutong!I18 -> 166.39 | H18: =Lambak!G18+Lambak!H18+Lambak!I18 -> 166.39 | I18: =SUM(D18:H18) -> 831.95
C19: Barang Harian Serbaguna | D19: =Tungku!G19+Tungku!H19+Tungku!I19 -> 84.8 | E19: =Salar!G19+Salar!H19+Salar!I19 -> 62.99 | F19: =Bengkurong!G19+Bengkurong!H19+Bengkurong!I19 -> 39.5 | G19: =Tutong!G19+Tutong!H19+Tutong!I19 -> 1.6 | H19: =Lambak!G19+Lambak!H19+Lambak!I19 -> 13.4 | I19: =SUM(D19:H19) -> 202.29
C20: Foods & Drink | D20: =Tungku!G20+Tungku!H20+Tungku!I20 -> 0 | E20: =Salar!G20+Salar!H20+Salar!I20 -> 0 | F20: =Bengkurong!G20+Bengkurong!H20+Bengkurong!I20 -> 0 | G20: =Tutong!G20+Tutong!H20+Tutong!I20 -> 0 | H20: =Lambak!G20+Lambak!H20+Lambak!I20 -> 0 | I20: =SUM(D20:H20) -> 0
C21: Management Fee | D21: =Tungku!G21+Tungku!H21+Tungku!I21 -> 750 | E21: =Salar!G21+Salar!H21+Salar!I21 -> 750 | F21: =Bengkurong!G21+Bengkurong!H21+Bengkurong!I21 -> 750 | G21: =Tutong!G21+Tutong!H21+Tutong!I21 -> 750 | H21: =Lambak!G21+Lambak!H21+Lambak!I21 -> 750 | I21: =SUM(D21:H21) -> 3750
C22: Total OPEX | D22: =SUM(D14:D21) -> 11941.45 | E22: =SUM(E14:E21) -> 8098.92 | F22: =SUM(F14:F21) -> 4648.2 | G22: =SUM(G14:G21) -> 3733.07 | H22: =SUM(H14:H21) -> 4281.48 | I22: =SUM(D22:H22) -> 32703.12
C23: Total Expeses | D23: =SUM(D12,D22) -> 28070.4 | E23: =SUM(E12,E22) -> 16319.48 | F23: =SUM(F12,F22) -> 12362.87 | G23: =SUM(G12,G22) -> 12181.22 | H23: =SUM(H12,H22) -> 11136.18 | I23: =SUM(I12,I22) -> 80070.15
C24: EBITDA (Earning Before interest, tax, depreciation, amortisation | D24: =Tungku!G24+Tungku!H24+Tungku!I24 -> 3001.29 | E24: =Salar!G24+Salar!H24+Salar!I24 -> -1295 | F24: =Bengkurong!G24+Bengkurong!H24+Bengkurong!I24 -> 5807.14 | G24: =Tutong!G24+Tutong!H24+Tutong!I24 -> 1495.52 | H24: =Lambak!G24+Lambak!H24+Lambak!I24 -> -3649.18 | I24: =SUM(D24:H24) -> 5359.77
C25: Asset Depreciation | D25: =Tungku!D25+Tungku!E25+Tungku!F25 -> 425.01 | E25: =Salar!D25+Salar!E25+Salar!F25 -> 425.01 | F25: =Bengkurong!D25+Bengkurong!E25+Bengkurong!F25 -> 425.01 | G25: =Tutong!D25+Tutong!E25+Tutong!F25 -> 425.01 | H25: =Lambak!D25+Lambak!E25+Lambak!F25 -> 425.01 | I25: =SUM(D25:H25) -> 2125.05
C26: NET PROFIT | D26: =Tungku!G26+Tungku!H26+Tungku!I26 -> 2576.28 | E26: =Salar!G26+Salar!H26+Salar!I26 -> -1720.01 | F26: =Bengkurong!G26+Bengkurong!H26+Bengkurong!I26 -> 5382.13 | G26: =Tutong!G26+Tutong!H26+Tutong!I26 -> 1070.51 | H26: =Lambak!G26+Lambak!H26+Lambak!I26 -> -4074.19 | I26: =SUM(D26:H26) -> 3234.72
C28: Profit Margin | D28: =D26/D3 -> 0.082914061 | E28: =E26/E3 -> -0.1144805 | F28: =F26/F3 -> 0.29620952 | G28: =G26/G3 -> 0.081242401 | H28: =H26/H3 -> -0.54416856 | I28: =I26/I3 -> 0.038086931

Sheet Tungku
B1: Kadai Tungku | C1: Revenue Hust Brew | G1: 202.3 | H1: 124.4 | I1: 107.6
D2: Jan | E2: Feb | F2: Mar | G2: Apr | H2: May | I2: Jun | J2: Jul | K2: Aug | L2: Sep | M2: Oct | N2: Nov | O2: Dec | P2: YTD
C3: Revenue | D3: 8175.1 | E3: 9010.34 | F3: 17390.89 | G3: =12524.55+202.3 -> 12726.85 | H3: =9056.42+H1 -> 9180.82 | I3: =9056.42+I1 -> 9164.02 | J3: 0 | K3: 0 | L3: 0 | M3: 0 | N3: 0 | O3: 0 | P3: =SUM(D3:O3) -> 65648.02
B4: Cost of Services | C4: Water Bill | D4: 150 | E4: 100 | F4: 200 | G4: 200 | H4: 200 | I4: 200 | J4: 0 | K4: 0 | L4: 0 | M4: 0 | N4: 0 | O4: 0 | P4: =SUM(D4:O4) -> 1050
C5: Electricity Bill | D5: 200 | E5: 0 | F5: 120 | G5: 170 | H5: 100 | I5: 150 | J5: 0 | K5: 0 | L5: 0 | M5: 0 | N5: 0 | O5: 0 | P5: =SUM(D5:O5) -> 740
C6: Car Wash Shampoo & Tyre Shine + Car Wax | D6: 475 | E6: 239.2 | F6: 592.6 | G6: 506 | H6: 399.2 | I6: 344 | J6: 0 | K6: 0 | L6: 0 | M6: 0 | N6: 0 | O6: 0 | P6: =SUM(D6:O6) -> 2556
C7: Staff Wages | D7: 2453.6 | E7: 2530.55 | F7: 2604.75 | G7: 2936.2 | H7: 3496.34 | I7: 3623.27 | J7: 0 | K7: 0 | L7: 0 | M7: 0 | N7: 0 | O7: 0 | P7: =SUM(D7:O7) -> 17644.71
C8: Part-timer Wages | D8: 863 | E8: 673 | F8: 1094 | G8: 1253 | H8: 595 | I8: 385 | J8: 0 | K8: 0 | L8: 0 | M8: 0 | N8: 0 | O8: 0 | P8: =SUM(D8:O8) -> 4863
C9: Bonus | D9: 25 | E9: 25 | F9: 1472 | G9: 0 | H9: 0 | I9: 0 | J9: 0 | K9: 0 | L9: 0 | M9: 0 | N9: 0 | O9: 0
C10: Miscellaneous | D10: 0 | E10: 35 | F10: 80 | G10: 465.04 | H10: 0 | I10: 626.5 | J10: 0 | K10: 0 | L10: 0 | M10: 0 | N10: 0 | O10: 0
C11: Maintenance & Repair | D11: 0 | E11: 0 | F11: 130 | G11: 479.4 | H11: 0 | I11: 0 | J11: 0 | K11: 0 | L11: 0 | M11: 0 | N11: 0 | O11: 0
C12: Total COS | D12: =SUM(D4:D11) -> 4166.6 | E12: =SUM(E4:E11) -> 3602.75 | F12: =SUM(F4:F11) -> 6293.35 | G12: =SUM(G4:G11) -> 6009.64 | H12: =SUM(H4:H11) -> 4790.54 | I12: =SUM(I4:I11) -> 5328.77 | J12: =SUM(J4:J11) -> 0 | K12: =SUM(K4:K11) -> 0 | ... O12: =SUM(O4:O11) -> 0 | P12: =SUM(D12:O12) -> 30191.65
C13: Gross Profit | D13: =D3-D12 -> 4008.5 | E13: =E3-E12 -> 5407.59 | F13: =F3-F12 -> 11097.54 | G13: =G3-G12 -> 6717.21 | H13: =H3-H12 -> 4390.28 | I13: =I3-I12 -> 3835.25 | J13: =J3-J12 -> 0 | K13: =K3-K12 -> 0 | ... O13: =O3-O12 -> 0 | P13: =SUM(D13:O13) -> 35456.37
B14: Operating Expense | C14: Total Units Rental | D14: 3300 | E14: 3300 | F14: 3300 | G14: 3300 | H14: 3300 | I14: 3300 | J14: 0 | K14: 0 | L14: 0 | M14: 0 | N14: 0 | O14: 0 | P14: =SUM(D14:O14) -> 19800
C15: Point-of-Sale System | D15: 30 | E15: 30 | F15: 30 | G15: 30 | H15: 30 | I15: 0 | J15: 0 | K15: 0 | L15: 0 | M15: 0 | N15: 0 | O15: 0 | P15: =SUM(D15:O15) -> 150
C16: Wifi Internet | D16: 0 | E16: 38 | F16: 86 | G16: 33 | H16: 63 | I16: 78 | J16: 0 | K16: 0 | L16: 0 | M16: 0 | N16: 0 | O16: 0 | P16: =SUM(D16:O16) -> 298
C17: SPK | D17: 172.77 | E17: 172.77 | F17: 230.36 | G17: 230.36 | H17: 287.95 | I17: 287.95 | J17: 0 | K17: 0 | L17: 0 | M17: 0 | N17: 0 | O17: 0 | P17: =SUM(D17:O17) -> 1382.16
C18: Connecteam (Employmee Management App) | D18: 55 | E18: 55 | F18: 55 | G18: =278.05/5 -> 55.61 | H18: 54.37 | I18: 56.41 | J18: 0 | K18: 0 | L18: 0 | M18: 0 | N18: 0 | O18: 0 | P18: =SUM(D18:O18) -> 331.39
C19: Barang Harian Serbaguna | D19: 5.9 | E19: 11.2 | F19: 20 | G19: 58.8 | H19: 14 | I19: 12 | J19: 0 | K19: 0 | L19: 0 | M19: 0 | N19: 0 | O19: 0 | P19: =SUM(D19:O19) -> 121.9
C20: Foods & Drink | D20: 0 | E20: 98 | F20: 101.37 | G20: 0 | H20: 0 | I20: 0 | J20: 0 | K20: 0 | L20: 0 | M20: 0 | N20: 0 | O20: 0 | P20: =SUM(D20:O20) -> 199.37
C21: Management Fee | D21: 250 | E21: 250 | F21: 250 | G21: 250 | H21: 250 | I21: 250 | J21: 0 | K21: 0 | L21: 0 | M21: 0 | N21: 0 | O21: 0 | P21: =SUM(D21:O21) -> 1500
C22: Total OPEX | D22: =SUM(D14:D21) -> 3813.67 | E22: =SUM(E14:E21) -> 3954.97 | F22: =SUM(F14:F21) -> 4072.73 | G22: =SUM(G14:G21) -> 3957.77 | H22: =SUM(H14:H21) -> 3999.32 | I22: =SUM(I14:I21) -> 3984.36 | J22: =SUM(J14:J21) -> 0 | K22: =SUM(K14:K21) -> 0 | ... O22: =SUM(O14:O21) -> 0 | P22: =SUM(D22:O22) -> 23782.82
C23: Total Expeses | D23: =SUM(D12,D22) -> 7980.27 | E23: =SUM(E12,E22) -> 7557.72 | F23: =SUM(F12,F22) -> 10366.08 | G23: =SUM(G12,G22) -> 9967.41 | H23: =SUM(H12,H22) -> 8789.86 | I23: =SUM(I12,I22) -> 9313.13 | J23: =SUM(J12,J22) -> 0 | K23: =SUM(K12,K22) -> 0 | ... P23: =SUM(P12,P22) -> 53974.47
C24: EBITDA (Earning Before interest, tax, depreciation, amortisation | D24: =D3-D12-D22 -> 194.83 | E24: =E3-E12-E22 -> 1452.62 | F24: =F3-F12-F22 -> 7024.81 | G24: =G3-G12-G22 -> 2759.44 | H24: =H3-H12-H22 -> 390.96 | I24: =I3-I12-I22 -> -149.11 | J24: =J3-J12-J22 -> 0 | K24: =K3-K12-K22 -> 0 | ... O24: =O3-O12-O22 -> 0 | P24: =SUM(D24:O24) -> 11673.55
C25: Asset Depreciation | D25: 141.67 | E25: 141.67 | F25: 141.67 | G25: 141.67 | H25: 141.67 | I25: 141.67 | P25: =SUM(D25:O25) -> 850.02
C26: NET PROFIT | D26: =D24-D25 -> 53.16 | E26: =E24-E25 -> 1310.95 | F26: =F24-F25 -> 6883.14 | G26: =G24-G25 -> 2617.77 | H26: =H24-H25 -> 249.29 | I26: =I24-I25 -> -290.78 | J26: =J24-J25 -> 0 | K26: =K24-K25 -> 0 | ... P26: =P24-P25 -> 10823.53
C28: Net Profit Margin | D28: =D26/D3 -> 0.0065026728 | E28: =E26/E3 -> 0.14549395 | F28: =F26/F3 -> 0.39578998 | G28: =G26/G3 -> 0.20568876 | H28: =H26/H3 -> 0.027153348 | I28: =I26/I3 -> -0.031730616 | J28: =J26/J3 -> #DIV/0! | K28: =K26/K3 -> #DIV/0! | ... P28: =P26/P3 -> 0.16487215
C29: remarks | D29: Hujan labat, 3/4 of the month, active weather and flood | E29: Hujan labat, 3/4 of the month, active weather and flood | F29: Surge of Revenue from a combination of Very Good weather and Festive Hari Raya Season | G29: Good weather, however Tungku is rejuvenated with new installed window wash bay | H29: hujan half of the month | I29: hujan half of the month

Sheet Salar
B1: Kadai Salar
D2: Jan | E2: Feb | F2: Mar | G2: Apr | H2: May | I2: Jun | J2: Jul | K2: Aug | L2: Sep | M2: Oct | N2: Nov | O2: Dec | P2: YTD
C3: Revenue | D3: 4650.92 | E3: 5570.84 | F3: 10266.02 | G3: 6067.29 | H3: 4179.24 | I3: 4777.95 | J3: 0 | K3: 0 | L3: 0 | M3: 0 | N3: 0 | O3: 0 | P3: =SUM(D3:O3) -> 35512.26
B4: Cost of Services | C4: Water Bill | D4: 150 | E4: 100 | F4: 0 | G4: 100 | H4: 100 | I4: 100 | J4: 0 | K4: 0 | L4: 0 | M4: 0 | N4: 0 | O4: 0 | P4: =SUM(D4:O4) -> 550
C5: Electricity Bill | D5: 100 | E5: 80 | F5: 80 | G5: 80 | H5: 100 | I5: 50 | J5: 0 | K5: 0 | L5: 0 | M5: 0 | N5: 0 | O5: 0 | P5: =SUM(D5:O5) -> 490
C6: Car Wash Shampoo & Tyre Shine + Car Wax | D6: 407 | E6: 149.5 | F6: 606.3 | G6: 405.9 | H6: 245.4 | I6: 304 | J6: 0 | K6: 0 | L6: 0 | M6: 0 | N6: 0 | O6: 0 | P6: =SUM(D6:O6) -> 2118.1
C7: Staff Wages | D7: 833.93 | E7: 221.12 | F7: 345.19 | G7: 1060.13 | H7: 1085.22 | I7: 1621.43 | J7: 0 | K7: 0 | L7: 0 | M7: 0 | N7: 0 | O7: 0 | P7: =SUM(D7:O7) -> 5167.02
C8: Part-timer Wages | D8: 1041 | E8: 1487 | F8: 1652 | G8: 1223 | H8: 1215 | I8: 511 | J8: 0 | K8: 0 | L8: 0 | M8: 0 | N8: 0 | O8: 0 | P8: =SUM(D8:O8) -> 7129
C9: Bonus | D9: 20 | E9: 0 | F9: 930 | G9: 5 | H9: 0 | I9: 0 | J9: 0 | K9: 0 | L9: 0 | M9: 0 | N9: 0 | O9: 0
C10: Miscellaneous | D10: 0 | E10: 89 | F10: 13 | G10: =4 -> 4 | H10: 10.48 | I10: 0 | J10: 0 | K10: 0 | L10: 0 | M10: 0 | N10: 0 | O10: 0
C11: Maintenance & Repair | D11: 0 | E11: 694.4 | F11: 160 | G11: 0 | H11: 0 | I11: 0 | J11: 0 | K11: 0 | L11: 0 | M11: 0 | N11: 0 | O11: 0
C12: Total COS | D12: =SUM(D4:D11) -> 2551.93 | E12: =SUM(E4:E11) -> 2821.02 | F12: =SUM(F4:F11) -> 3786.49 | G12: =SUM(G4:G11) -> 2878.03 | H12: =SUM(H4:H11) -> 2756.1 | I12: =SUM(I4:I11) -> 2586.43 | J12: =SUM(J4:J11) -> 0 | K12: =SUM(K4:K11) -> 0 | ... O12: =SUM(O4:O11) -> 0 | P12: =SUM(D12:O12) -> 17380
C13: Gross Profit | D13: =D3-D12 -> 2098.99 | E13: =E3-E12 -> 2749.82 | F13: =F3-F12 -> 6479.53 | G13: =G3-G12 -> 3189.26 | H13: =H3-H12 -> 1423.14 | I13: =I3-I12 -> 2191.52 | J13: =J3-J12 -> 0 | K13: =K3-K12 -> 0 | ... O13: =O3-O12 -> 0 | P13: =SUM(D13:O13) -> 18132.26
B14: Operating Expense | C14: Total Units Rental | D14: 2200 | E14: 2200 | F14: 2200 | G14: 2200 | H14: 2200 | I14: 2200 | J14: 0 | K14: 0 | L14: 0 | M14: 0 | N14: 0 | O14: 0 | P14: =SUM(D14:O14) -> 13200
C15: Point-of-Sale System | D15: 30 | E15: 30 | F15: 30 | G15: 30 | H15: 30 | I15: 0 | J15: 0 | K15: 0 | L15: 0 | M15: 0 | N15: 0 | O15: 0 | P15: =SUM(D15:O15) -> 150
C16: Wifi Internet | D16: 0 | E16: 38 | F16: 86 | G16: 33 | H16: 38 | I16: 43 | J16: 0 | K16: 0 | L16: 0 | M16: 0 | N16: 0 | O16: 0 | P16: =SUM(D16:O16) -> 238
C17: SPK | D17: 57.59 | E17: 57.59 | F17: 57.59 | G17: =57.59*2 -> 115.18 | H17: 115.18 | I17: 115.18 | J17: 0 | K17: 0 | L17: 0 | M17: 0 | N17: 0 | O17: 0 | P17: =SUM(D17:O17) -> 518.31
C18: Connecteam (Employmee Management App) | D18: 55 | E18: 55 | F18: 55 | G18: =278.05/5 -> 55.61 | H18: 54.37 | I18: 56.41 | J18: 0 | K18: 0 | L18: 0 | M18: 0 | N18: 0 | O18: 0 | P18: =SUM(D18:O18) -> 331.39
C19: Barang Harian Serbaguna | D19: 0 | E19: 8.99 | F19: 33 | G19: 11.99 | H19: 16.7 | I19: 34.3 | J19: 0 | K19: 0 | L19: 0 | M19: 0 | N19: 0 | O19: 0 | P19: =SUM(D19:O19) -> 104.98
C20: Foods & Drink | D20: 0 | E20: 0 | F20: 96.68 | G20: 0 | H20: 0 | I20: 0 | J20: 0 | K20: 0 | L20: 0 | M20: 0 | N20: 0 | O20: 0 | P20: =SUM(D20:O20) -> 96.68
C21: Management Fee | D21: 250 | E21: 250 | F21: 250 | G21: 250 | H21: 250 | I21: 250 | J21: 0 | K21: 0 | L21: 0 | M21: 0 | N21: 0 | O21: 0 | P21: =SUM(D21:O21) -> 1500
C22: Total OPEX | D22: =SUM(D14:D21) -> 2592.59 | E22: =SUM(E14:E21) -> 2639.58 | F22: =SUM(F14:F21) -> 2808.27 | G22: =SUM(G14:G21) -> 2695.78 | H22: =SUM(H14:H21) -> 2704.25 | I22: =SUM(I14:I21) -> 2698.89 | J22: =SUM(J14:J21) -> 0 | K22: =SUM(K14:K21) -> 0 | ... O22: =SUM(O14:O21) -> 0 | P22: =SUM(D22:O22) -> 16139.36
C23: Total Expeses | D23: =SUM(D12,D22) -> 5144.52 | E23: =SUM(E12,E22) -> 5460.6 | F23: =SUM(F12,F22) -> 6594.76 | G23: =SUM(G12,G22) -> 5573.81 | H23: =SUM(H12,H22) -> 5460.35 | I23: =SUM(I12,I22) -> 5285.32 | J23: =SUM(J12,J22) -> 0 | K23: =SUM(K12,K22) -> 0 | ... P23: =SUM(P12,P22) -> 33519.36
C24: EBITDA (Earning Before interest, tax, depreciation, amortisation | D24: =D3-D12-D22 -> -493.6 | E24: =E3-E12-E22 -> 110.24 | F24: =F3-F12-F22 -> 3671.26 | G24: =G3-G12-G22 -> 493.48 | H24: =H3-H12-H22 -> -1281.11 | I24: =I3-I12-I22 -> -507.37 | J24: =J3-J12-J22 -> 0 | K24: =K3-K12-K22 -> 0 | ... O24: =O3-O12-O22 -> 0 | P24: =SUM(D24:O24) -> 1992.9
C25: Asset Depreciation | D25: 141.67 | E25: 141.67 | F25: 141.67 | G25: 141.67 | H25: 141.67 | I25: 141.67 | P25: =SUM(D25:O25) -> 850.02
C26: NET PROFIT | D26: =D24-D25 -> -635.27 | E26: =E24-E25 -> -31.43 | F26: =F24-F25 -> 3529.59 | G26: =G24-G25 -> 351.81 | H26: =H24-H25 -> -1422.78 | I26: =I24-I25 -> -649.04 | J26: =J24-J25 -> 0 | K26: =K24-K25 -> 0 | ... P26: =P24-P25 -> 1142.88
C28: Net Profit Margin | D28: =D26/D3 -> -0.13659018 | E28: =E26/E3 -> -0.0056418781 | F28: =F26/F3 -> 0.34381289 | G28: =G26/G3 -> 0.057984702 | H28: =H26/H3 -> -0.34043989 | I28: =I26/I3 -> -0.13584068 | J28: =J26/J3 -> #DIV/0! | K28: =K26/K3 -> #DIV/0! | ... P28: =P26/P3 -> 0.032182688
C29: remarks | D29: Hujan labat, 3/4 of the month, active weather and flood | E29: Hujan labat, 3/4 of the month, active weather and flood | F29: Surge of Revenue from a combination of Very Good weather and Festive Hari Raya Season

Sheet Bengkurong
B1: Kadai Bengkurong
D2: Jan | E2: Feb | F2: Mar | G2: Apr | H2: May | I2: Jun | J2: Jul | K2: Aug | L2: Sep | M2: Oct | N2: Nov | O2: Dec | P2: YTD
C3: Revenue | D3: 5047.04 | E3: 5153.58 | F3: 10649.57 | G3: 7222.28 | H3: 5128.01 | I3: 5819.72 | J3: 0 | K3: 0 | L3: 0 | M3: 0 | N3: 0 | O3: 0 | P3: =SUM(D3:O3) -> 39020.2
B4: Cost of Services | C4: Water Bill | D4: 100 | E4: 80 | F4: 114 | G4: 100 | H4: 100 | I4: 50 | J4: 0 | K4: 0 | L4: 0 | M4: 0 | N4: 0 | O4: 0 | P4: =SUM(D4:O4) -> 544
C5: Electricity Bill | D5: 100 | E5: 110 | F5: 90 | G5: 100 | H5: 100 | I5: 100 | J5: 0 | K5: 0 | L5: 0 | M5: 0 | N5: 0 | O5: 0 | P5: =SUM(D5:O5) -> 600
C6: Car Wash Shampoo & Tyre Shine + Car Wax | D6: 429 | E6: 179.4 | F6: 559 | G6: 403 | H6: 201.4 | I6: 304 | J6: 0 | K6: 0 | L6: 0 | M6: 0 | N6: 0 | O6: 0 | P6: =SUM(D6:O6) -> 2075.8
C7: Staff Wages | D7: 1795.53 | E7: 1683.61 | F7: 1827.44 | G7: 1966.56 | H7: 2064.96 | I7: 2094.75 | J7: 0 | K7: 0 | L7: 0 | M7: 0 | N7: 0 | O7: 0 | P7: =SUM(D7:O7) -> 11432.85
C8: Part-timer Wages | D8: 0 | E8: 0 | F8: 189 | G8: 79 | H8: 0 | I8: 0 | J8: 0 | K8: 0 | L8: 0 | M8: 0 | N8: 0 | O8: 0 | P8: =SUM(D8:O8) -> 268
C9: Bonus | D9: 15 | E9: 0 | F9: 1258 | G9: 0 | H9: 0 | I9: 0 | J9: 0 | K9: 0 | L9: 0 | M9: 0 | N9: 0 | O9: 0
C10: Miscellaneous | D10: 0 | E10: 0 | F10: 178 | G10: 0 | H10: 0 | I10: 0 | J10: 0 | K10: 0 | L10: 0 | M10: 0 | N10: 0 | O10: 0
C11: Maintenance & Repair | E11: 0 | F11: 18 | G11: 49 | H11: 2 | I11: 0 | J11: 0 | K11: 0 | L11: 0 | M11: 0 | N11: 0 | O11: 0
C12: Total COS | D12: =SUM(D4:D11) -> 2439.53 | E12: =SUM(E4:E11) -> 2053.01 | F12: =SUM(F4:F11) -> 4233.44 | G12: =SUM(G4:G11) -> 2697.56 | H12: =SUM(H4:H11) -> 2468.36 | I12: =SUM(I4:I11) -> 2548.75 | J12: =SUM(J4:J11) -> 0 | K12: =SUM(K4:K11) -> 0 | ... O12: =SUM(O4:O11) -> 0 | P12: =SUM(D12:O12) -> 16440.65
C13: Gross Profit | D13: =D3-D12 -> 2607.51 | E13: =E3-E12 -> 3100.57 | F13: =F3-F12 -> 6416.13 | G13: =G3-G12 -> 4524.72 | H13: =H3-H12 -> 2659.65 | I13: =I3-I12 -> 3270.97 | J13: =J3-J12 -> 0 | K13: =K3-K12 -> 0 | ... O13: =O3-O12 -> 0 | P13: =SUM(D13:O13) -> 22579.55
B14: Operating Expense | C14: Total Units Rental | D14: 1000 | E14: 1000 | F14: 1000 | G14: 1000 | H14: 1000 | I14: 1000 | J14: 0 | K14: 0 | L14: 0 | M14: 0 | N14: 0 | O14: 0 | P14: =SUM(D14:O14) -> 6000
C15: Point-of-Sale System | D15: 30 | E15: 30 | F15: 30 | G15: 30 | H15: 30 | I15: 0 | J15: 0 | K15: 0 | L15: 0 | M15: 0 | N15: 0 | O15: 0 | P15: =SUM(D15:O15) -> 150
C16: Wifi Internet | D16: 0 | E16: 0 | F16: 124 | G16: 33 | H16: 38 | I16: 43 | J16: 0 | K16: 0 | L16: 0 | M16: 0 | N16: 0 | O16: 0 | P16: =SUM(D16:O16) -> 238
C17: SPK | D17: 172.77 | E17: 172.77 | F17: 172.77 | G17: 172.77 | H17: 172.77 | I17: 172.77 | J17: 0 | K17: 0 | L17: 0 | M17: 0 | N17: 0 | O17: 0 | P17: =SUM(D17:O17) -> 1036.62
C18: Connecteam (Employmee Management App) | D18: 55 | E18: 55 | F18: 55 | G18: =278.05/5 -> 55.61 | H18: 54.37 | I18: 56.41 | J18: 0 | K18: 0 | L18: 0 | M18: 0 | N18: 0 | O18: 0 | P18: =SUM(D18:O18) -> 331.39
C19: Barang Harian Serbaguna | D19: 6 | E19: 7 | F19: 24 | G19: 0 | H19: 33 | I19: 6.5 | J19: 0 | K19: 0 | L19: 0 | M19: 0 | N19: 0 | O19: 0 | P19: =SUM(D19:O19) -> 76.5
C20: Foods & Drink | F20: 92 | G20: 0 | H20: 0 | I20: 0 | J20: 0 | K20: 0 | L20: 0 | M20: 0 | N20: 0 | O20: 0 | P20: =SUM(D20:O20) -> 92
C21: Management Fee | D21: 250 | E21: 250 | F21: 250 | G21: 250 | H21: 250 | I21: 250 | J21: 0 | K21: 0 | L21: 0 | M21: 0 | N21: 0 | O21: 0 | P21: =SUM(D21:O21) -> 1500
C22: Total OPEX | D22: =SUM(D14:D21) -> 1513.77 | E22: =SUM(E14:E21) -> 1514.77 | F22: =SUM(F14:F21) -> 1747.77 | G22: =SUM(G14:G21) -> 1541.38 | H22: =SUM(H14:H21) -> 1578.14 | I22: =SUM(I14:I21) -> 1528.68 | J22: =SUM(J14:J21) -> 0 | K22: =SUM(K14:K21) -> 0 | ... O22: =SUM(O14:O21) -> 0 | P22: =SUM(D22:O22) -> 9424.51
C23: Total Expeses | D23: =SUM(D12,D22) -> 3953.3 | E23: =SUM(E12,E22) -> 3567.78 | F23: =SUM(F12,F22) -> 5981.21 | G23: =SUM(G12,G22) -> 4238.94 | H23: =SUM(H12,H22) -> 4046.5 | I23: =SUM(I12,I22) -> 4077.43 | J23: =SUM(J12,J22) -> 0 | K23: =SUM(K12,K22) -> 0 | ... P23: =SUM(P12,P22) -> 25865.16
C24: EBITDA (Earning Before interest, tax, depreciation, amortisation | D24: =D3-D12-D22 -> 1093.74 | E24: =E3-E12-E22 -> 1585.8 | F24: =F3-F12-F22 -> 4668.36 | G24: =G3-G12-G22 -> 2983.34 | H24: =H3-H12-H22 -> 1081.51 | I24: =I3-I12-I22 -> 1742.29 | J24: =J3-J12-J22 -> 0 | K24: =K3-K12-K22 -> 0 | ... O24: =O3-O12-O22 -> 0 | P24: =SUM(D24:O24) -> 13155.04
C25: Asset Depreciation | D25: 141.67 | E25: 141.67 | F25: 141.67 | G25: 141.67 | H25: 141.67 | I25: 141.67 | P25: =SUM(D25:O25) -> 850.02
C26: NET PROFIT | D26: =D24-D25 -> 952.07 | E26: =E24-E25 -> 1444.13 | F26: =F24-F25 -> 4526.69 | G26: =G24-G25 -> 2841.67 | H26: =H24-H25 -> 939.84 | I26: =I24-I25 -> 1600.62 | J26: =J24-J25 -> 0 | K26: =K24-K25 -> 0 | ... P26: =P24-P25 -> 12305.02
C28: Net Profit Margin | D28: =D26/D3 -> 0.18863928 | E28: =E26/E3 -> 0.2802188 | F28: =F26/F3 -> 0.42505848 | G28: =G26/G3 -> 0.39345885 | H28: =H26/H3 -> 0.18327577 | I28: =I26/I3 -> 0.27503385 | J28: =J26/J3 -> #DIV/0! | K28: =K26/K3 -> #DIV/0! | ... P28: =P26/P3 -> 0.31535
C29: remarks | D29: Hujan labat, 3/4 of the month, active weather and flood | E29: Hujan labat, 3/4 of the month, active weather and flood | F29: Surge of Revenue from a combination of Very Good weather and Festive Hari Raya Season

Sheet Tutong
B1: Kadai Tutong
D2: Jan | E2: Feb | F2: Mar | G2: Apr | H2: May | I2: Jun | J2: Jul | K2: Aug | L2: Sep | M2: Oct | N2: Nov | O2: Dec | P2: YTD
C3: Revenue | D3: 4375.18 | E3: 4308 | F3: 10011.52 | G3: 5768.44 | H3: 3492.5 | I3: 3915.8 | J3: 0 | K3: 0 | L3: 0 | M3: 0 | N3: 0 | O3: 0 | P3: =SUM(D3:O3) -> 31871.44
B4: Cost of Services | C4: Water Bill | D4: 90 | E4: 30 | F4: 80 | G4: 100 | H4: 100 | I4: 0 | J4: 0 | K4: 0 | L4: 0 | M4: 0 | N4: 0 | O4: 0 | P4: =SUM(D4:O4) -> 400
C5: Electricity Bill | D5: 100 | E5: 50 | F5: 90 | G5: 80 | H5: 100 | I5: 100 | J5: 0 | K5: 0 | L5: 0 | M5: 0 | N5: 0 | O5: 0 | P5: =SUM(D5:O5) -> 520
C6: Car Wash Shampoo & Tyre Shine + Car Wax | D6: 108 | E6: 179.4 | F6: 536 | G6: 400 | H6: 383.4 | I6: 244.2 | J6: 0 | K6: 0 | L6: 0 | M6: 0 | N6: 0 | O6: 0 | P6: =SUM(D6:O6) -> 1851
C7: Staff Wages | D7: 1780.67 | E7: 1751.34 | F7: 1785.3 | G7: 2273.73 | H7: 2179.88 | I7: 2155.94 | J7: 0 | K7: 0 | L7: 0 | M7: 0 | N7: 0 | O7: 0 | P7: =SUM(D7:O7) -> 11926.86
C8: Part-timer Wages | D8: 335 | E8: 78 | F8: 395 | G8: 112 | H8: 84 | I8: 135 | J8: 0 | K8: 0 | L8: 0 | M8: 0 | N8: 0 | O8: 0 | P8: =SUM(D8:O8) -> 1139
C9: Bonus | D9: 10 | E9: 1.9 | F9: 1075 | G9: 0 | H9: 0 | I9: 0 | J9: 0 | K9: 0 | L9: 0 | M9: 0 | N9: 0 | O9: 0
C10: Miscellaneous | D10: 0 | E10: 0 | F10: 160 | G10: 0 | H10: 0 | I10: 0 | J10: 0 | K10: 0 | L10: 0 | M10: 0 | N10: 0 | O10: 0
C11: Maintenance & Repair | E11: 0 | F11: 80 | G11: 0 | H11: 0 | I11: 0 | J11: 0 | K11: 0 | L11: 0 | M11: 0 | N11: 0 | O11: 0
C12: Total COS | D12: =SUM(D4:D11) -> 2423.67 | E12: =SUM(E4:E11) -> 2090.64 | F12: =SUM(F4:F11) -> 4201.3 | G12: =SUM(G4:G11) -> 2965.73 | H12: =SUM(H4:H11) -> 2847.28 | I12: =SUM(I4:I11) -> 2635.14 | J12: =SUM(J4:J11) -> 0 | K12: =SUM(K4:K11) -> 0 | ... O12: =SUM(O4:O11) -> 0 | P12: =SUM(D12:O12) -> 17163.76
C13: Gross Profit | D13: =D3-D12 -> 1951.51 | E13: =E3-E12 -> 2217.36 | F13: =F3-F12 -> 5810.22 | G13: =G3-G12 -> 2802.71 | H13: =H3-H12 -> 645.22 | I13: =I3-I12 -> 1280.66 | J13: =J3-J12 -> 0 | K13: =K3-K12 -> 0 | ... O13: =O3-O12 -> 0 | P13: =SUM(D13:O13) -> 14707.68
B14: Operating Expense | C14: Total Units Rental | D14: 650 | E14: 650 | F14: 650 | G14: 650 | H14: 650 | I14: 650 | J14: 0 | K14: 0 | L14: 0 | M14: 0 | N14: 0 | O14: 0 | P14: =SUM(D14:O14) -> 3900
C15: Point-of-Sale System | D15: 30 | E15: 30 | F15: 30 | G15: 30 | H15: 30 | I15: 0 | J15: 0 | K15: 0 | L15: 0 | M15: 0 | N15: 0 | O15: 0 | P15: =SUM(D15:O15) -> 150
C16: Wifi Internet | D16: 0 | E16: 0 | F16: 124 | G16: 33 | H16: 38 | I16: 43 | J16: 0 | K16: 0 | L16: 0 | M16: 0 | N16: 0 | O16: 0 | P16: =SUM(D16:O16) -> 238
C17: SPK | D17: 230.36 | E17: 230.36 | F17: 230.36 | G17: 230.36 | H17: 230.36 | I17: 230.36 | J17: 0 | K17: 0 | L17: 0 | M17: 0 | N17: 0 | O17: 0 | P17: =SUM(D17:O17) -> 1382.16
C18: Connecteam (Employmee Management App) | D18: 55 | E18: 55 | F18: 55 | G18: =278.05/5 -> 55.61 | H18: 54.37 | I18: 56.41 | J18: 0 | K18: 0 | L18: 0 | M18: 0 | N18: 0 | O18: 0 | P18: =SUM(D18:O18) -> 331.39
C19: Barang Harian Serbaguna | D19: 0 | E19: 10.6 | F19: 16.5 | G19: 1.6 | H19: 0 | I19: 0 | J19: 0 | K19: 0 | L19: 0 | M19: 0 | N19: 0 | O19: 0 | P19: =SUM(D19:O19) -> 28.7
C20: Foods & Drink | F20: 79.74 | G20: 0 | H20: 0 | I20: 0 | J20: 0 | K20: 0 | L20: 0 | M20: 0 | N20: 0 | O20: 0 | P20: =SUM(D20:O20) -> 79.74
C21: Management Fee | D21: 250 | E21: 250 | F21: 250 | G21: 250 | H21: 250 | I21: 250 | J21: 0 | K21: 0 | L21: 0 | M21: 0 | N21: 0 | O21: 0 | P21: =SUM(D21:O21) -> 1500
C22: Total OPEX | D22: =SUM(D14:D20) -> 965.36 | E22: =SUM(E14:E20) -> 975.96 | F22: =SUM(F14:F20) -> 1185.6 | G22: =SUM(G14:G21) -> 1250.57 | H22: =SUM(H14:H20) -> 1002.73 | I22: =SUM(I14:I20) -> 979.77 | J22: =SUM(J14:J20) -> 0 | K22: =SUM(K14:K20) -> 0 | L22: =SUM(L14:L20) -> 0 | M22: =SUM(M14:M20) -> 0 | N22: =SUM(N14:N20) -> 0 | O22: =SUM(O14:O20) -> 0 | P22: =SUM(D22:O22) -> 6359.99
C23: Total Expeses | D23: =SUM(D12,D22) -> 3389.03 | E23: =SUM(E12,E22) -> 3066.6 | F23: =SUM(F12,F22) -> 5386.9 | G23: =SUM(G12,G22) -> 4216.3 | H23: =SUM(H12,H22) -> 3850.01 | I23: =SUM(I12,I22) -> 3614.91 | J23: =SUM(J12,J22) -> 0 | K23: =SUM(K12,K22) -> 0 | ... P23: =SUM(P12,P22) -> 23523.75
C24: EBITDA (Earning Before interest, tax, depreciation, amortisation | D24: =D3-D12-D22 -> 986.15 | E24: =E3-E12-E22 -> 1241.4 | F24: =F3-F12-F22 -> 4624.62 | G24: =G3-G12-G22 -> 1552.14 | H24: =H3-H12-H22 -> -357.51 | I24: =I3-I12-I22 -> 300.89 | J24: =J3-J12-J22 -> 0 | K24: =K3-K12-K22 -> 0 | ... O24: =O3-O12-O22 -> 0 | P24: =SUM(D24:O24) -> 8347.69
C25: Asset Depreciation | D25: 141.67 | E25: 141.67 | F25: 141.67 | G25: 141.67 | H25: 141.67 | I25: 141.67 | P25: =SUM(D25:O25) -> 850.02
C26: NET PROFIT | D26: =D24-D25 -> 844.48 | E26: =E24-E25 -> 1099.73 | F26: =F24-F25 -> 4482.95 | G26: =G24-G25 -> 1410.47 | H26: =H24-H25 -> -499.18 | I26: =I24-I25 -> 159.22 | J26: =J24-J25 -> 0 | K26: =K24-K25 -> 0 | ... P26: =P24-P25 -> 7497.67
C28: Net Profit Margin | D28: =D26/D3 -> 0.19301606 | E28: =E26/E3 -> 0.25527623 | F28: =F26/F3 -> 0.44777916 | G28: =G26/G3 -> 0.24451498 | H28: =H26/H3 -> -0.14292913 | I28: =I26/I3 -> 0.040660912 | J28: =J26/J3 -> #DIV/0! | K28: =K26/K3 -> #DIV/0! | ... P28: =P26/P3 -> 0.23524729
C29: remarks | D29: Hujan labat, 3/4 of the month, active weather and flood | E29: Hujan labat, 3/4 of the month, active weather and flood | F29: Surge of Revenue from a combination of Very Good weather and Festive Hari Raya Season

Sheet Lambak
B1: Kadai Lambak
D2: Jan | E2: Feb | F2: Mar | G2: Apr | H2: May | I2: Jun | J2: Jul | K2: Aug | L2: Sep | M2: Oct | N2: Nov | O2: Dec | P2: YTD
C3: Revenue | D3: 1504 | E3: 1560 | F3: 3975.7 | G3: 2862 | H3: 2199 | I3: 2426 | J3: 0 | K3: 0 | L3: 0 | M3: 0 | N3: 0 | O3: 0 | P3: =SUM(D3:O3) -> 14526.7
B4: Cost of Services | C4: Water Bill | D4: 0 | E4: 0 | F4: 0 | G4: 0 | H4: 0 | I4: 0 | J4: 0 | K4: 0 | L4: 0 | M4: 0 | N4: 0 | O4: 0 | P4: =SUM(D4:O4) -> 0
C5: Electricity Bill | D5: 60 | E5: 80 | F5: 30 | G5: 140 | H5: 100 | I5: 100 | J5: 0 | K5: 0 | L5: 0 | M5: 0 | N5: 0 | O5: 0 | P5: =SUM(D5:O5) -> 510
C6: Car Wash Shampoo & Tyre Shine + Car Wax | D6: 45 | E6: 149.5 | F6: 239.6 | G6: 427.9 | H6: 149.5 | I6: 140 | J6: 0 | K6: 0 | L6: 0 | M6: 0 | N6: 0 | O6: 0 | P6: =SUM(D6:O6) -> 1151.5
C7: Staff Wages | D7: 1004.77 | E7: 1225.55 | F7: 1244.3 | G7: 1518.69 | H7: 1617.34 | I7: 1414.57 | J7: 0 | K7: 0 | L7: 0 | M7: 0 | N7: 0 | O7: 0 | P7: =SUM(D7:O7) -> 8025.22
C8: Part-timer Wages | D8: 566 | E8: 207 | F8: 399 | G8: 333.7 | H8: 148 | I8: 265 | J8: 0 | K8: 0 | L8: 0 | M8: 0 | N8: 0 | O8: 0 | P8: =SUM(D8:O8) -> 1918.7
C9: Bonus | D9: 0 | E9: 0 | F9: 730 | G9: 0 | H9: 0 | I9: 0 | J9: 0 | K9: 0 | L9: 0 | M9: 0 | N9: 0 | O9: 0 | P9: =SUM(D9:O9) -> 730
C10: Miscellaneous | D10: 0 | E10: 0 | F10: 0 | G10: 500 | H10: 0 | I10: 0 | J10: 0 | K10: 0 | L10: 0 | M10: 0 | N10: 0 | O10: 0 | P10: =SUM(D10:O10) -> 500
C11: Maintenance & Repair | D11: 0 | E11: 0 | F11: 550 | G11: 0 | H11: 0 | I11: 0 | J11: 0 | K11: 0 | L11: 0 | M11: 0 | N11: 0 | O11: 0 | P11: =SUM(D11:O11) -> 550
C12: Total COS | D12: =SUM(D4:D11) -> 1675.77 | E12: =SUM(E4:E11) -> 1662.05 | F12: =SUM(F4:F11) -> 3192.9 | G12: =SUM(G4:G11) -> 2920.29 | H12: =SUM(H4:H11) -> 2014.84 | I12: =SUM(I4:I11) -> 1919.57 | J12: =SUM(J4:J11) -> 0 | K12: =SUM(K4:K11) -> 0 | ... O12: =SUM(O4:O11) -> 0 | P12: =SUM(D12:O12) -> 13385.42
C13: Gross Profit | D13: =D3-D12 -> -171.77 | E13: =E3-E12 -> -102.05 | F13: =F3-F12 -> 782.8 | G13: =G3-G12 -> -58.29 | H13: =H3-H12 -> 184.16 | I13: =I3-I12 -> 506.43 | J13: =J3-J12 -> 0 | K13: =K3-K12 -> 0 | ... O13: =O3-O12 -> 0 | P13: =SUM(D13:O13) -> 1141.28
B14: Operating Expense | C14: Total Units Rental | D14: 1000 | E14: 1000 | F14: 1000 | G14: 1000 | H14: 1000 | I14: 1000 | J14: 0 | K14: 0 | L14: 0 | M14: 0 | N14: 0 | O14: 0 | P14: =SUM(D14:O14) -> 6000
C15: Point-of-Sale System | D15: 30 | E15: 30 | F15: 30 | G15: 30 | H15: 30 | I15: 0 | J15: 0 | K15: 0 | L15: 0 | M15: 0 | N15: 0 | O15: 0 | P15: =SUM(D15:O15) -> 150
C16: Wifi Internet | D16: 0 | E16: 43 | F16: 28 | G16: 38 | H16: 38 | I16: 43 | J16: 0 | K16: 0 | L16: 0 | M16: 0 | N16: 0 | O16: 0 | P16: =SUM(D16:O16) -> 190
C17: SPK | D17: 57.59 | E17: 57.59 | F17: 57.59 | G17: 57.59 | H17: 57.55 | I17: 57.55 | J17: 0 | K17: 0 | L17: 0 | M17: 0 | N17: 0 | O17: 0 | P17: =SUM(D17:O17) -> 345.46
C18: Connecteam (Employmee Management App) | D18: 55 | E18: 55 | F18: 55 | G18: =278.05/5 -> 55.61 | H18: 54.37 | I18: 56.41 | J18: 0 | K18: 0 | L18: 0 | M18: 0 | N18: 0 | O18: 0 | P18: =SUM(D18:O18) -> 331.39
C19: Barang Harian Serbaguna | D19: 6.7 | E19: 0 | F19: 146.1 | G19: 7.5 | H19: 0 | I19: 5.9 | J19: 0 | K19: 0 | L19: 0 | M19: 0 | N19: 0 | O19: 0 | P19: =SUM(D19:O19) -> 166.2
C20: Foods & Drink | D20: 0 | E20: 0 | F20: 28.3 | G20: 0 | H20: 0 | I20: 0 | J20: 0 | K20: 0 | L20: 0 | M20: 0 | N20: 0 | O20: 0 | P20: =SUM(D20:O20) -> 28.3
C21: Management Fee | D21: 250 | E21: 250 | F21: 250 | G21: 250 | H21: 250 | I21: 250 | J21: 0 | K21: 0 | L21: 0 | M21: 0 | N21: 0 | O21: 0 | P21: =SUM(D21:O21) -> 1500
C22: Total OPEX | D22: =SUM(D14:D21) -> 1399.29 | E22: =SUM(E14:E21) -> 1435.59 | F22: =SUM(F14:F21) -> 1594.99 | G22: =SUM(G14:G21) -> 1438.7 | H22: =SUM(H14:H21) -> 1429.92 | I22: =SUM(I14:I21) -> 1412.86 | J22: =SUM(J14:J21) -> 0 | K22: =SUM(K14:K21) -> 0 | ... O22: =SUM(O14:O21) -> 0 | P22: =SUM(D22:O22) -> 8711.35
C23: Total Expeses | D23: =SUM(D12,D22) -> 3075.06 | E23: =SUM(E12,E22) -> 3097.64 | F23: =SUM(F12,F22) -> 4787.89 | G23: =SUM(G12,G22) -> 4358.99 | H23: =SUM(H12,H22) -> 3444.76 | I23: =SUM(I12,I22) -> 3332.43 | J23: =SUM(J12,J22) -> 0 | K23: =SUM(K12,K22) -> 0 | ... P23: =SUM(P12,P22) -> 22096.77
C24: EBITDA (Earning Before interest, tax, depreciation, amortisation | D24: =D3-D12-D22 -> -1571.06 | E24: =E3-E12-E22 -> -1537.64 | F24: =F3-F12-F22 -> -812.19 | G24: =G3-G12-G22 -> -1496.99 | H24: =H3-H12-H22 -> -1245.76 | I24: =I3-I12-I22 -> -906.43 | J24: =J3-J12-J22 -> 0 | K24: =K3-K12-K22 -> 0 | ... O24: =O3-O12-O22 -> 0 | P24: =SUM(D24:O24) -> -7570.07
C25: Asset Depreciation | D25: 141.67 | E25: 141.67 | F25: 141.67 | G25: 141.67 | H25: 141.67 | I25: 141.67 | P25: =SUM(D25:O25) -> 850.02
C26: NET PROFIT | D26: =D24-D25 -> -1712.73 | E26: =E24-E25 -> -1679.31 | F26: =F24-F25 -> -953.86 | G26: =G24-G25 -> -1638.66 | H26: =H24-H25 -> -1387.43 | I26: =I24-I25 -> -1048.1 | J26: =J24-J25 -> 0 | K26: =K24-K25 -> 0 | ... P26: =P24-P25 -> -8420.09
C28: Net Profit Margin | D28: =D26/D3 -> -1.1387832 | E28: =E26/E3 -> -1.0764808 | F28: =F26/F3 -> -0.23992253 | G28: =G26/G3 -> -0.57255765 | H28: =H26/H3 -> -0.63093679 | I28: =I26/I3 -> -0.43202803 | J28: =J26/J3 -> #DIV/0! | K28: =K26/K3 -> #DIV/0! | ... P28: =P26/P3 -> -0.57962855
C29: remarks | D29: Hujan labat, 3/4 of the month, active weather and flood | E29: Hujan labat, 3/4 of the month, active weather and flood | F29: Surge of Revenue from a combination of Very Good weather and Festive Hari Raya Season | G29: Good weather, sales is picking up, extra expense on Pylon Signage marketing strategy.

Sheet Dart
B2: Dart | C2: August | D2: September | E2: October
B3: 1st | C3: 0 | D3: 10 | E3: 17
B4: 2nd | C4: 0 | D4: 7 | E4: 10
B5: 3rd | C5: 6 | D5: 10 | E5: 10
B6: 4th | C6: 0 | D6: 17 | E6: 17
B7: 5th | C7: 0 | D7: 17 | E7: 10
B8: 6th | C8: 0 | D8: 17 | E8: 17
B9: 7th | C9: 0 | D9: 17 | E9: 7
B10: 8th | C10: 0 | D10: 10 | E10: 17
B11: 9th | C11: 0 | D11: 17 | E11: 10
B12: 10th | C12: 7 | D12: 17 | E12: 17
B13: 11th | C13: 10 | D13: 7 | E13: 10
B14: 12th | C14: 17 | D14: 17 | E14: 17
... B33: 31st | C33: 7 | D33: 0 | E33: 27
C34: =SUM(C3:C33) -> 326 | D34: =SUM(D3:D33) -> 313 | E34: =SUM(E3:E33) -> 470

Sheet Overall
B1: Overall Total
D2: Jan | E2: Feb | F2: Mar | G2: Apr | H2: May | I2: Jun | J2: Jul | K2: Aug | L2: Sep | M2: Oct | N2: Nov | O2: Dec | P2: YTD
C3: Revenue | D3: =Tungku!D3+Salar!D3+Bengkurong!D3+Tutong!D3+Lambak!D3 -> 23752.24 | E3: =Tungku!E3+Salar!E3+Bengkurong!E3+Tutong!E3+Lambak!E3 -> 25602.76 | F3: =Tungku!F3+Salar!F3+Bengkurong!F3+Tutong!F3+Lambak!F3 -> 52293.7 | G3: =Tungku!G3+Salar!G3+Bengkurong!G3+Tutong!G3+Lambak!G3 -> 34646.86 | H3: =Tungku!H3+Salar!H3+Bengkurong!H3+Tutong!H3+Lambak!H3 -> 24179.57 | I3: =Tungku!I3+Salar!I3+Bengkurong!I3+Tutong!I3+Lambak!I3 -> 26103.49 | J3: =Tungku!J3+Salar!J3+Bengkurong!J3+Tutong!J3+Lambak!J3 -> 0 | K3: =Tungku!K3+Salar!K3+Bengkurong!K3+Tutong!K3+Lambak!K3 -> 0 | ... O3: =Tungku!O3+Salar!O3+Bengkurong!O3+Tutong!O3+Lambak!O3 -> 0 | P3: =SUM(D3:O3) -> 186578.62
B4: Cost of Services | C4: Water Bill | D4: =Tungku!D4+Salar!D4+Bengkurong!D4+Tutong!D4+Lambak!D4 -> 490 | E4: =Tungku!E4+Salar!E4+Bengkurong!E4+Tutong!E4+Lambak!E4 -> 310 | F4: =Tungku!F4+Salar!F4+Bengkurong!F4+Tutong!F4+Lambak!F4 -> 394 | G4: =Tungku!G4+Salar!G4+Bengkurong!G4+Tutong!G4+Lambak!G4 -> 500 | H4: =Tungku!H4+Salar!H4+Bengkurong!H4+Tutong!H4+Lambak!H4 -> 500 | I4: =Tungku!I4+Salar!I4+Bengkurong!I4+Tutong!I4+Lambak!I4 -> 350 | J4: =Tungku!J4+Salar!J4+Bengkurong!J4+Tutong!J4+Lambak!J4 -> 0 | K4: =Tungku!K4+Salar!K4+Bengkurong!K4+Tutong!K4+Lambak!K4 -> 0 | ... O4: =Tungku!O4+Salar!O4+Bengkurong!O4+Tutong!O4+Lambak!O4 -> 0 | P4: =SUM(D4:O4) -> 2544
C5: Electricity Bill | D5: =Tungku!D5+Salar!D5+Bengkurong!D5+Tutong!D5+Lambak!D5 -> 560 | E5: =Tungku!E5+Salar!E5+Bengkurong!E5+Tutong!E5+Lambak!E5 -> 320 | F5: =Tungku!F5+Salar!F5+Bengkurong!F5+Tutong!F5+Lambak!F5 -> 410 | G5: =Tungku!G5+Salar!G5+Bengkurong!G5+Tutong!G5+Lambak!G5 -> 570 | H5: =Tungku!H5+Salar!H5+Bengkurong!H5+Tutong!H5+Lambak!H5 -> 500 | I5: =Tungku!I5+Salar!I5+Bengkurong!I5+Tutong!I5+Lambak!I5 -> 500 | J5: =Tungku!J5+Salar!J5+Bengkurong!J5+Tutong!J5+Lambak!J5 -> 0 | K5: =Tungku!K5+Salar!K5+Bengkurong!K5+Tutong!K5+Lambak!K5 -> 0 | ... O5: =Tungku!O5+Salar!O5+Bengkurong!O5+Tutong!O5+Lambak!O5 -> 0 | P5: =SUM(D5:O5) -> 2860
C6: Car Wash Shampoo & Tyre Shine + Car Wax | D6: =Tungku!D6+Salar!D6+Bengkurong!D6+Tutong!D6+Lambak!D6 -> 1464 | E6: =Tungku!E6+Salar!E6+Bengkurong!E6+Tutong!E6+Lambak!E6 -> 897 | F6: =Tungku!F6+Salar!F6+Bengkurong!F6+Tutong!F6+Lambak!F6 -> 2533.5 | G6: =Tungku!G6+Salar!G6+Bengkurong!G6+Tutong!G6+Lambak!G6 -> 2142.8 | H6: =Tungku!H6+Salar!H6+Bengkurong!H6+Tutong!H6+Lambak!H6 -> 1378.9 | I6: =Tungku!I6+Salar!I6+Bengkurong!I6+Tutong!I6+Lambak!I6 -> 1336.2 | J6: =Tungku!J6+Salar!J6+Bengkurong!J6+Tutong!J6+Lambak!J6 -> 0 | K6: =Tungku!K6+Salar!K6+Bengkurong!K6+Tutong!K6+Lambak!K6 -> 0 | ... O6: =Tungku!O6+Salar!O6+Bengkurong!O6+Tutong!O6+Lambak!O6 -> 0 | P6: =SUM(D6:O6) -> 9752.4
C7: Staff Wages | D7: =Tungku!D7+Salar!D7+Bengkurong!D7+Tutong!D7+Lambak!D7 -> 7868.5 | E7: =Tungku!E7+Salar!E7+Bengkurong!E7+Tutong!E7+Lambak!E7 -> 7412.17 | F7: =Tungku!F7+Salar!F7+Bengkurong!F7+Tutong!F7+Lambak!F7 -> 7806.98 | G7: =Tungku!G7+Salar!G7+Bengkurong!G7+Tutong!G7+Lambak!G7 -> 9755.31 | H7: =Tungku!H7+Salar!H7+Bengkurong!H7+Tutong!H7+Lambak!H7 -> 10443.74 | I7: =Tungku!I7+Salar!I7+Bengkurong!I7+Tutong!I7+Lambak!I7 -> 10909.96 | J7: =Tungku!J7+Salar!J7+Bengkurong!J7+Tutong!J7+Lambak!J7 -> 0 | K7: =Tungku!K7+Salar!K7+Bengkurong!K7+Tutong!K7+Lambak!K7 -> 0 | ... O7: =Tungku!O7+Salar!O7+Bengkurong!O7+Tutong!O7+Lambak!O7 -> 0 | P7: =SUM(D7:O7) -> 54196.66
C8: Part-timer Wages | D8: =Tungku!D8+Salar!D8+Bengkurong!D8+Tutong!D8+Lambak!D8 -> 2805 | E8: =Tungku!E8+Salar!E8+Bengkurong!E8+Tutong!E8+Lambak!E8 -> 2445 | F8: =Tungku!F8+Salar!F8+Bengkurong!F8+Tutong!F8+Lambak!F8 -> 3729 | G8: =Tungku!G8+Salar!G8+Bengkurong!G8+Tutong!G8+Lambak!G8 -> 3000.7 | H8: =Tungku!H8+Salar!H8+Bengkurong!H8+Tutong!H8+Lambak!H8 -> 2042 | I8: =Tungku!I8+Salar!I8+Bengkurong!I8+Tutong!I8+Lambak!I8 -> 1296 | J8: =Tungku!J8+Salar!J8+Bengkurong!J8+Tutong!J8+Lambak!J8 -> 0 | K8: =Tungku!K8+Salar!K8+Bengkurong!K8+Tutong!K8+Lambak!K8 -> 0 | ... O8: =Tungku!O8+Salar!O8+Bengkurong!O8+Tutong!O8+Lambak!O8 -> 0 | P8: =SUM(D8:O8) -> 15317.7
C9: Bonus | D9: =Tungku!D9+Salar!D9+Bengkurong!D9+Tutong!D9+Lambak!D9 -> 70 | E9: =Tungku!E9+Salar!E9+Bengkurong!E9+Tutong!E9+Lambak!E9 -> 26.9 | F9: =Tungku!F9+Salar!F9+Bengkurong!F9+Tutong!F9+Lambak!F9 -> 5465 | G9: =Tungku!G9+Salar!G9+Bengkurong!G9+Tutong!G9+Lambak!G9 -> 5 | H9: =Tungku!H9+Salar!H9+Bengkurong!H9+Tutong!H9+Lambak!H9 -> 0 | I9: =Tungku!I9+Salar!I9+Bengkurong!I9+Tutong!I9+Lambak!I9 -> 0 | J9: =Tungku!J9+Salar!J9+Bengkurong!J9+Tutong!J9+Lambak!J9 -> 0 | K9: =Tungku!K9+Salar!K9+Bengkurong!K9+Tutong!K9+Lambak!K9 -> 0 | ... O9: =Tungku!O9+Salar!O9+Bengkurong!O9+Tutong!O9+Lambak!O9 -> 0 | P9: =SUM(D9:O9) -> 5566.9
C10: Miscellaneous | D10: =Tungku!D10+Salar!D10+Bengkurong!D10+Tutong!D10+Lambak!D10 -> 0 | E10: =Tungku!E10+Salar!E10+Bengkurong!E10+Tutong!E10+Lambak!E10 -> 124 | F10: =Tungku!F10+Salar!F10+Bengkurong!F10+Tutong!F10+Lambak!F10 -> 431 | G10: =Tungku!G10+Salar!G10+Bengkurong!G10+Tutong!G10+Lambak!G10 -> 969.04 | H10: =Tungku!H10+Salar!H10+Bengkurong!H10+Tutong!H10+Lambak!H10 -> 10.48 | I10: =Tungku!I10+Salar!I10+Bengkurong!I10+Tutong!I10+Lambak!I10 -> 626.5 | J10: =Tungku!J10+Salar!J10+Bengkurong!J10+Tutong!J10+Lambak!J10 -> 0 | K10: =Tungku!K10+Salar!K10+Bengkurong!K10+Tutong!K10+Lambak!K10 -> 0 | ... O10: =Tungku!O10+Salar!O10+Bengkurong!O10+Tutong!O10+Lambak!O10 -> 0 | P10: =SUM(D10:O10) -> 2161.02
C11: Maintenance & Repair | D11: =Tungku!D11+Salar!D11+Bengkurong!D11+Tutong!D11+Lambak!D11 -> 0 | E11: =Tungku!E11+Salar!E11+Bengkurong!E11+Tutong!E11+Lambak!E11 -> 694.4 | F11: =Tungku!F11+Salar!F11+Bengkurong!F11+Tutong!F11+Lambak!F11 -> 938 | G11: =Tungku!G11+Salar!G11+Bengkurong!G11+Tutong!G11+Lambak!G11 -> 528.4 | H11: =Tungku!H11+Salar!H11+Bengkurong!H11+Tutong!H11+Lambak!H11 -> 2 | I11: =Tungku!I11+Salar!I11+Bengkurong!I11+Tutong!I11+Lambak!I11 -> 0 | J11: =Tungku!J11+Salar!J11+Bengkurong!J11+Tutong!J11+Lambak!J11 -> 0 | K11: =Tungku!K11+Salar!K11+Bengkurong!K11+Tutong!K11+Lambak!K11 -> 0 | ... O11: =Tungku!O11+Salar!O11+Bengkurong!O11+Tutong!O11+Lambak!O11 -> 0 | P11: =SUM(D11:O11) -> 2162.8
C12: Total COS | D12: =SUM(D4:D11) -> 13257.5 | E12: =SUM(E4:E11) -> 12229.47 | F12: =SUM(F4:F11) -> 21707.48 | G12: =SUM(G4:G11) -> 17471.25 | H12: =SUM(H4:H11) -> 14877.12 | I12: =SUM(I4:I11) -> 15018.66 | J12: =SUM(J4:J11) -> 0 | K12: =SUM(K4:K11) -> 0 | ... O12: =SUM(O4:O11) -> 0 | P12: =SUM(D12:O12) -> 94561.48
C13: Gross Profit | D13: =D3-D12 -> 10494.74 | E13: =E3-E12 -> 13373.29 | F13: =F3-F12 -> 30586.22 | G13: =G3-G12 -> 17175.61 | H13: =H3-H12 -> 9302.45 | I13: =I3-I12 -> 11084.83 | J13: =J3-J12 -> 0 | K13: =K3-K12 -> 0 | ... O13: =O3-O12 -> 0 | P13: =SUM(D13:O13) -> 92017.14
B14: Operating Expense | C14: Total Units Rental | D14: =Tungku!D14+Salar!D14+Bengkurong!D14+Tutong!D14+Lambak!D14 -> 8150 | E14: =Tungku!E14+Salar!E14+Bengkurong!E14+Tutong!E14+Lambak!E14 -> 8150 | F14: =Tungku!F14+Salar!F14+Bengkurong!F14+Tutong!F14+Lambak!F14 -> 8150 | G14: =Tungku!G14+Salar!G14+Bengkurong!G14+Tutong!G14+Lambak!G14 -> 8150 | H14: =Tungku!H14+Salar!H14+Bengkurong!H14+Tutong!H14+Lambak!H14 -> 8150 | I14: =Tungku!I14+Salar!I14+Bengkurong!I14+Tutong!I14+Lambak!I14 -> 8150 | J14: =Tungku!J14+Salar!J14+Bengkurong!J14+Tutong!J14+Lambak!J14 -> 0 | K14: =Tungku!K14+Salar!K14+Bengkurong!K14+Tutong!K14+Lambak!K14 -> 0 | ... O14: =Tungku!O14+Salar!O14+Bengkurong!O14+Tutong!O14+Lambak!O14 -> 0 | P14: =SUM(D14:O14) -> 48900
C15: Point-of-Sale System | D15: =Tungku!D15+Salar!D15+Bengkurong!D15+Tutong!D15+Lambak!D15 -> 150 | E15: =Tungku!E15+Salar!E15+Bengkurong!E15+Tutong!E15+Lambak!E15 -> 150 | F15: =Tungku!F15+Salar!F15+Bengkurong!F15+Tutong!F15+Lambak!F15 -> 150 | G15: =Tungku!G15+Salar!G15+Bengkurong!G15+Tutong!G15+Lambak!G15 -> 150 | H15: =Tungku!H15+Salar!H15+Bengkurong!H15+Tutong!H15+Lambak!H15 -> 150 | I15: =Tungku!I15+Salar!I15+Bengkurong!I15+Tutong!I15+Lambak!I15 -> 0 | J15: =Tungku!J15+Salar!J15+Bengkurong!J15+Tutong!J15+Lambak!J15 -> 0 | K15: =Tungku!K15+Salar!K15+Bengkurong!K15+Tutong!K15+Lambak!K15 -> 0 | ... O15: =Tungku!O15+Salar!O15+Bengkurong!O15+Tutong!O15+Lambak!O15 -> 0 | P15: =SUM(D15:O15) -> 750
C16: Wifi Internet | D16: =Tungku!D16+Salar!D16+Bengkurong!D16+Tutong!D16+Lambak!D16 -> 0 | E16: =Tungku!E16+Salar!E16+Bengkurong!E16+Tutong!E16+Lambak!E16 -> 119 | F16: =Tungku!F16+Salar!F16+Bengkurong!F16+Tutong!F16+Lambak!F16 -> 448 | G16: =Tungku!G16+Salar!G16+Bengkurong!G16+Tutong!G16+Lambak!G16 -> 170 | H16: =Tungku!H16+Salar!H16+Bengkurong!H16+Tutong!H16+Lambak!H16 -> 215 | I16: =Tungku!I16+Salar!I16+Bengkurong!I16+Tutong!I16+Lambak!I16 -> 250 | J16: =Tungku!J16+Salar!J16+Bengkurong!J16+Tutong!J16+Lambak!J16 -> 0 | K16: =Tungku!K16+Salar!K16+Bengkurong!K16+Tutong!K16+Lambak!K16 -> 0 | ... O16: =Tungku!O16+Salar!O16+Bengkurong!O16+Tutong!O16+Lambak!O16 -> 0 | P16: =SUM(D16:O16) -> 1202
C17: SPK | D17: =Tungku!D17+Salar!D17+Bengkurong!D17+Tutong!D17+Lambak!D17 -> 691.08 | E17: =Tungku!E17+Salar!E17+Bengkurong!E17+Tutong!E17+Lambak!E17 -> 691.08 | F17: =Tungku!F17+Salar!F17+Bengkurong!F17+Tutong!F17+Lambak!F17 -> 748.67 | G17: =Tungku!G17+Salar!G17+Bengkurong!G17+Tutong!G17+Lambak!G17 -> 806.26 | H17: =Tungku!H17+Salar!H17+Bengkurong!H17+Tutong!H17+Lambak!H17 -> 863.81 | I17: =Tungku!I17+Salar!I17+Bengkurong!I17+Tutong!I17+Lambak!I17 -> 863.81 | J17: =Tungku!J17+Salar!J17+Bengkurong!J17+Tutong!J17+Lambak!J17 -> 0 | K17: =Tungku!K17+Salar!K17+Bengkurong!K17+Tutong!K17+Lambak!K17 -> 0 | ... O17: =Tungku!O17+Salar!O17+Bengkurong!O17+Tutong!O17+Lambak!O17 -> 0 | P17: =SUM(D17:O17) -> 4664.71
C18: Connecteam (Employmee Management App) | D18: =Tungku!D18+Salar!D18+Bengkurong!D18+Tutong!D18+Lambak!D18 -> 275 | E18: =Tungku!E18+Salar!E18+Bengkurong!E18+Tutong!E18+Lambak!E18 -> 275 | F18: =Tungku!F18+Salar!F18+Bengkurong!F18+Tutong!F18+Lambak!F18 -> 275 | G18: =Tungku!G18+Salar!G18+Bengkurong!G18+Tutong!G18+Lambak!G18 -> 278.05 | H18: =Tungku!H18+Salar!H18+Bengkurong!H18+Tutong!H18+Lambak!H18 -> 271.85 | I18: =Tungku!I18+Salar!I18+Bengkurong!I18+Tutong!I18+Lambak!I18 -> 282.05 | J18: =Tungku!J18+Salar!J18+Bengkurong!J18+Tutong!J18+Lambak!J18 -> 0 | K18: =Tungku!K18+Salar!K18+Bengkurong!K18+Tutong!K18+Lambak!K18 -> 0 | ... O18: =Tungku!O18+Salar!O18+Bengkurong!O18+Tutong!O18+Lambak!O18 -> 0 | P18: =SUM(D18:O18) -> 1656.95
C19: Barang Harian Serbaguna | D19: =Tungku!D19+Salar!D19+Bengkurong!D19+Tutong!D19+Lambak!D19 -> 18.6 | E19: =Tungku!E19+Salar!E19+Bengkurong!E19+Tutong!E19+Lambak!E19 -> 37.79 | F19: =Tungku!F19+Salar!F19+Bengkurong!F19+Tutong!F19+Lambak!F19 -> 239.6 | G19: =Tungku!G19+Salar!G19+Bengkurong!G19+Tutong!G19+Lambak!G19 -> 79.89 | H19: =Tungku!H19+Salar!H19+Bengkurong!H19+Tutong!H19+Lambak!H19 -> 63.7 | I19: =Tungku!I19+Salar!I19+Bengkurong!I19+Tutong!I19+Lambak!I19 -> 58.7 | J19: =Tungku!J19+Salar!J19+Bengkurong!J19+Tutong!J19+Lambak!J19 -> 0 | K19: =Tungku!K19+Salar!K19+Bengkurong!K19+Tutong!K19+Lambak!K19 -> 0 | ... O19: =Tungku!O19+Salar!O19+Bengkurong!O19+Tutong!O19+Lambak!O19 -> 0 | P19: =SUM(D19:O19) -> 498.28
C20: Foods & Drink | D20: =Tungku!D20+Salar!D20+Bengkurong!D20+Tutong!D20+Lambak!D20 -> 0 | E20: =Tungku!E20+Salar!E20+Bengkurong!E20+Tutong!E20+Lambak!E20 -> 98 | F20: =Tungku!F20+Salar!F20+Bengkurong!F20+Tutong!F20+Lambak!F20 -> 398.09 | G20: =Tungku!G20+Salar!G20+Bengkurong!G20+Tutong!G20+Lambak!G20 -> 0 | H20: =Tungku!H20+Salar!H20+Bengkurong!H20+Tutong!H20+Lambak!H20 -> 0 | I20: =Tungku!I20+Salar!I20+Bengkurong!I20+Tutong!I20+Lambak!I20 -> 0 | J20: =Tungku!J20+Salar!J20+Bengkurong!J20+Tutong!J20+Lambak!J20 -> 0 | K20: =Tungku!K20+Salar!K20+Bengkurong!K20+Tutong!K20+Lambak!K20 -> 0 | ... O20: =Tungku!O20+Salar!O20+Bengkurong!O20+Tutong!O20+Lambak!O20 -> 0 | P20: =SUM(D20:O20) -> 496.09
C21: Management Fee | D21: =Tungku!D21+Salar!D21+Bengkurong!D21+Tutong!D21+Lambak!D21 -> 1250 | E21: =Tungku!E21+Salar!E21+Bengkurong!E21+Tutong!E21+Lambak!E21 -> 1250 | F21: =Tungku!F21+Salar!F21+Bengkurong!F21+Tutong!F21+Lambak!F21 -> 1250 | G21: =Tungku!G21+Salar!G21+Bengkurong!G21+Tutong!G21+Lambak!G21 -> 1250 | H21: =Tungku!H21+Salar!H21+Bengkurong!H21+Tutong!H21+Lambak!H21 -> 1250 | I21: =Tungku!I21+Salar!I21+Bengkurong!I21+Tutong!I21+Lambak!I21 -> 1250 | J21: =Tungku!J21+Salar!J21+Bengkurong!J21+Tutong!J21+Lambak!J21 -> 0 | K21: =Tungku!K21+Salar!K21+Bengkurong!K21+Tutong!K21+Lambak!K21 -> 0 | ... O21: =Tungku!O21+Salar!O21+Bengkurong!O21+Tutong!O21+Lambak!O21 -> 0 | P21: =SUM(D21:O21) -> 7500
C22: Total OPEX | D22: =SUM(D14:D21) -> 10534.68 | E22: =SUM(E14:E21) -> 10770.87 | F22: =SUM(F14:F21) -> 11659.36 | G22: =SUM(G14:G21) -> 10884.2 | H22: =SUM(H14:H21) -> 10964.36 | I22: =SUM(I14:I21) -> 10854.56 | J22: =SUM(J14:J21) -> 0 | K22: =SUM(K14:K21) -> 0 | ... O22: =SUM(O14:O21) -> 0 | P22: =SUM(D22:O22) -> 65668.03
C23: Total Expeses | D23: =SUM(D12,D22) -> 23792.18 | E23: =SUM(E12,E22) -> 23000.34 | F23: =SUM(F12,F22) -> 33366.84 | G23: =SUM(G12,G22) -> 28355.45 | H23: =SUM(H12,H22) -> 25841.48 | I23: =SUM(I12,I22) -> 25873.22 | J23: =SUM(J12,J22) -> 0 | K23: =SUM(K12,K22) -> 0 | ... O23: =SUM(O12,O22) -> 0 | P23: =SUM(D23:O23) -> 160229.51
C24: EBITDA (Earning Before interest, tax, depreciation, amortisation | D24: =Tungku!D24+Salar!D24+Bengkurong!D24+Tutong!D24+Lambak!D24 -> 210.06 | E24: =Tungku!E24+Salar!E24+Bengkurong!E24+Tutong!E24+Lambak!E24 -> 2852.42 | F24: =Tungku!F24+Salar!F24+Bengkurong!F24+Tutong!F24+Lambak!F24 -> 19176.86 | G24: =Tungku!G24+Salar!G24+Bengkurong!G24+Tutong!G24+Lambak!G24 -> 6291.41 | H24: =Tungku!H24+Salar!H24+Bengkurong!H24+Tutong!H24+Lambak!H24 -> -1411.91 | I24: =Tungku!I24+Salar!I24+Bengkurong!I24+Tutong!I24+Lambak!I24 -> 480.27 | J24: =J3-J12-J22 -> 0 | K24: =K3-K12-K22 -> 0 | L24: =L3-L12-L22 -> 0 | M24: =M3-M12-M22 -> 0 | N24: =N3-N12-N22 -> 0 | O24: =O3-O12-O22 -> 0 | P24: =SUM(D24:O24) -> 27599.11
C25: Asset Depreciation | D25: =Tungku!D25+Salar!D25+Bengkurong!D25+Tutong!D25+Lambak!D25 -> 708.35 | E25: =Tungku!E25+Salar!E25+Bengkurong!E25+Tutong!E25+Lambak!E25 -> 708.35 | F25: =Tungku!F25+Salar!F25+Bengkurong!F25+Tutong!F25+Lambak!F25 -> 708.35 | G25: =Tungku!G25+Salar!G25+Bengkurong!G25+Tutong!G25+Lambak!G25 -> 708.35 | H25: =Tungku!H25+Salar!H25+Bengkurong!H25+Tutong!H25+Lambak!H25 -> 708.35 | I25: =Tungku!I25+Salar!I25+Bengkurong!I25+Tutong!I25+Lambak!I25 -> 708.35 | J25: =Tungku!J25+Salar!J25+Bengkurong!J25+Tutong!J25+Lambak!J25 -> 0 | K25: =Tungku!K25+Salar!K25+Bengkurong!K25+Tutong!K25+Lambak!K25 -> 0 | ... O25: =Tungku!O25+Salar!O25+Bengkurong!O25+Tutong!O25+Lambak!O25 -> 0 | P25: =SUM(D25:O25) -> 4250.1
C26: NET PROFIT | D26: =D24-D25 -> -498.29 | E26: =E24-E25 -> 2144.07 | F26: =F24-F25 -> 18468.51 | G26: =G24-G25 -> 5583.06 | H26: =H24-H25 -> -2120.26 | I26: =I24-I25 -> -228.08 | J26: =J24-J25 -> 0 | K26: =K24-K25 -> 0 | ... P26: =P24-P25 -> 23349.01
C28: Net Profit Margin | D28: =D26/D3 -> -0.020978653 | E28: =E26/E3 -> 0.083743706 | F28: =F26/F3 -> 0.35316893 | G28: =G26/G3 -> 0.16114188 | H28: =H26/H3 -> -0.087688077 | I28: =I26/I3 -> -0.008737529 | J28: =J26/J3 -> #DIV/0! | K28: =K26/K3 -> #DIV/0! | ... P28: =P26/P3 -> 0.12514301
C29: Month | D29: January | E29: February | F29: March | G29: April | H29: May | I29: June
C30: Quarter 1 Insights remarks | D30: Hujan labat, 3/4 of the month, active weather and flood | E30: Hujan labat, 3/4 of the month, active weather and flood | F30: Surge of Revenue from a combination of Very Good weather and Festive Hari Raya Season | G30: Rejuvenated Tungku Branch as planned in Q1 Business Plan | H30: 1/2 month Rain | I30: 1/2 Month rain

Sheet MTD
C2: Days | D2: 31 | H2: MTD Performance
D3: Revenue | E3: Cost Per Day | F3: Net Profit | H3: Time Elapsed | I3: =D2/31 -> 1
B4: Fri | C4: 1st | D4: 334 | E4: 677.39167 | F4: =SUM($D$4:D4)-17397.85 -> -17063.85 | H4: Pandan | I4: =#REF!/#REF! -> #REF!
B5: Sat | C5: 2nd | D5: 1035 | E5: 677.39167 | F5: =SUM($D$4:D5)-17397.85 -> -16028.85 | H5: Tungku | I5: =(Tungku!O3/Tungku!N3)-I3 -> #DIV/0!
B6: Sun | C6: 3rd | D6: 1283 | E6: 677.39167 | F6: =SUM($D$4:D6)-17397.85 -> -14745.85 | H6: Salar | I6: =(#REF!/#REF!)-I3 -> #REF!
B7: Mon | C7: 4th | D7: 611 | E7: 677.39167 | F7: =SUM($D$4:D7)-17397.85 -> -14134.85 | H7: Overall | I7: =#REF!/#REF! -> #REF!
B8: Tue | C8: 5th | D8: 725 | E8: 677.39167 | F8: =SUM($D$4:D8)-17397.85 -> -13409.85
B9: Wed | C9: 6th | D9: 615 | E9: 677.39167 | F9: =SUM($D$4:D9)-17397.85 -> -12794.85
B10: Thu | C10: 7th | D10: 588 | E10: 677.39167 | F10: =SUM($D$4:D10)-17397.85 -> -12206.85
B11: Fri | C11: 8th | D11: 570 | E11: 677.39167 | F11: =SUM($D$4:D11)-17397.85 -> -11636.85
B12: Sat | C12: 9th | D12: 1072 | E12: 677.39167 | F12: =SUM($D$4:D12)-17397.85 -> -10564.85
B13: Sun | C13: 10th | D13: 1126 | E13: 677.39167 | F13: =SUM($D$4:D13)-17397.85 -> -9438.85
B14: Mon | C14: 11th | D14: 720 | E14: 677.39167 | F14: =SUM($D$4:D14)-17397.85 -> -8718.85
B15: Tue | C15: 12th | D15: 830 | E15: 677.39167 | F15: =SUM($D$4:D15)-17397.85 -> -7888.85
B16: Wed | C16: 13th | D16: 690 | E16: 677.39167 | F16: =SUM($D$4:D16)-17397.85 -> -7198.85
B17: Thu | C17: 14th | D17: 869 | E17: 677.39167 | F17: =SUM($D$4:D17)-17397.85 -> -6329.85
B18: Fri | C18: 15th | D18: 367 | E18: 677.39167 | F18: =SUM($D$4:D18)-17397.85 -> -5962.85
B19: Sat | C19: 16th | D19: 1137 | E19: 677.39167 | F19: =SUM($D$4:D19)-17397.85 -> -4825.85
... B34: Sun | C34: 31st | D34: 615 | E34: 677.39167 | F34: =SUM($D$4:D34)-17397.85 -> 8101.15

Sheet Sales
B2: Month | C2: No of Cars | D2: Rank | F2: Month | G2: Full Package | H2: Ratio | J2: Total Cars | K2: =SUM(C3:C13) -> #REF!
B3: Jan | C3: =#REF!/9.45 -> #REF! | F3: Jan | G3: =268+160+112 -> 540 | H3: =G3/C3 -> #REF! | J3: Runrate | K3: =AVERAGE(C3:C14) -> #REF!
B4: Feb | C4: =#REF!/9.42 -> #REF! | F4: Feb | G4: =242+65+11 -> 318 | H4: =G4/C4 -> #REF!
B5: Mar | C5: =#REF!/9.41 -> #REF! | D5: Highest | F5: Mar | G5: =387+78+36+18 -> 519 | H5: =G5/C5 -> #REF! | J5: Full Package | K5: October | L5: December | M5: Kadai | N5: Performance
B6: Apr | C6: =#REF!/9.67 -> #REF! | F6: Apr | G6: =447+168+106+88+6 -> 815 | H6: =G6/C6 -> #REF! | K6: 519 | L6: 519 | M6: Tungku | N6: =L6/K6 -> 1
B7: May | C7: =#REF!/9.53 -> #REF! | D7: Lowest | F7: May | G7: =417+84+29+16 -> 546 | H7: =G7/C7 -> #REF! | K7: 289 | L7: 341 | M7: Pandan | N7: =L7/K7 -> 1.1799308
B8: Jun | C8: =#REF!/9.71 -> #REF! | F8: Jun | G8: =349+138+36+12 -> 535 | H8: =G8/C8 -> #REF! | K8: 205 | L8: 198 | M8: Salar | N8: =L8/K8 -> 0.96585366
B9: Jul | C9: =#REF!/9.65 -> #REF! | F9: Jul | G9: =293+186+142+37+11 -> 669 | H9: =G9/C9 -> #REF! | J9: Total | K9: =SUM(K6:K8) -> 1013 | L9: =SUM(L6:L8) -> 1058 | M9: =L9/K9-1 -> 0.044422507 | N9: =L9/K9 -> 1.0444225
B10: Aug | C10: =#REF!/9.73 -> #REF! | D10: =C10/K3-1 -> #REF! | F10: Aug | G10: =369+223+189+31+6 -> 818 | H10: =G10/C10 -> #REF!
B11: Sep | C11: =#REF!/9.85 -> #REF! | D11: =C11/K3-1 -> #REF! | F11: Sep | G11: 803 | H11: =G11/C11 -> #REF!
B12: Oct | C12: =#REF!/10.06 -> #REF! | D12: =C12/K3-1 -> #REF! | F12: Oct | G12: 1013 | H12: =G12/C12 -> #REF!
B13: Nov | C13: =#REF!/10 -> #REF! | D13: =C13/K3-1 -> #REF! | F13: Nov | G13: 760 | H13: =G13/C13 -> #REF!
B14: Dec | C14: =#REF!/10.22 -> #REF! | D14: =C14/K3-1 -> #REF! | F14: Dec | G14: =L9 -> 1058 | H14: =G14/C14 -> #REF!

Sheet CAPEX
B4: Kadai Tutong
D5: Jan | E5: Feb | F5: Mar | G5: Apr | H5: May | I5: Jun | J5: Jul | K5: Aug | L5: Sep | M5: Oct | N5: Nov | O5: Dec | P5: YTD
C6: Investment | D6: 0 | E6: 0 | F6: 0 | G6: 0 | H6: 0 | I6: 0 | J6: 0 | K6: 0 | L6: 0 | M6: 0 | N6: 0 | O6: 0 | P6: =SUM(D6:O6) -> 0
B7: Fixed Cost | C7: Rental | D7: 0 | E7: 0 | F7: 0 | G7: 0 | H7: 0 | I7: 0 | J7: 0 | K7: 0 | L7: 0 | M7: 0 | N7: 0 | O7: 0 | P7: =SUM(D7:O7) -> 0
C8: Internet | D8: 0 | E8: 0 | F8: 0 | G8: 0 | H8: 0 | I8: 0 | J8: 0 | K8: 0 | L8: 0 | M8: 0 | N8: 0 | O8: 0 | P8: =SUM(D8:O8) -> 0
C9: POS | D9: 0 | E9: 0 | F9: 0 | G9: 0 | H9: 0 | I9: 0 | J9: 0 | K9: 0 | L9: 0 | M9: 0 | N9: 0 | O9: 0 | P9: =SUM(D9:O9) -> 0
C10: Electricity | D10: 0 | E10: 0 | F10: 0 | G10: 0 | H10: 0 | I10: 0 | J10: 0 | K10: 0 | L10: 0 | M10: 0 | N10: 0 | O10: 0 | P10: =SUM(D10:O10) -> 0
C11: Water | D11: 0 | E11: 0 | F11: 0 | G11: 0 | H11: 0 | I11: 0 | J11: 0 | K11: 0 | L11: 0 | M11: 0 | N11: 0 | O11: 0 | P11: =SUM(D11:O11) -> 0
C12: Total Fixed Cost | D12: =SUM(D7:D11) -> 0 | E12: =SUM(E7:E11) -> 0 | F12: =SUM(F7:F11) -> 0 | G12: =SUM(G7:G11) -> 0 | H12: =SUM(H7:H11) -> 0 | I12: =SUM(I7:I11) -> 0 | J12: =SUM(J7:J11) -> 0 | K12: =SUM(K7:K11) -> 0 | ... O12: =SUM(O7:O11) -> 0 | P12: =SUM(D12:O12) -> 0
B13: Variable Cost | C13: Shampoo, Turtle Wax, water wax | D13: 0 | E13: 0 | F13: 0 | G13: 0 | H13: 0 | I13: 0 | J13: 0 | K13: 0 | L13: 0 | M13: 0 | N13: 0 | O13: 0 | P13: =SUM(D13:O13) -> 0
C14: Barang Harian Serbaguna | D14: 0 | E14: 0 | F14: 0 | G14: 0 | H14: 0 | I14: 0 | J14: 0 | K14: 0 | L14: 0 | M14: 0 | N14: 0 | O14: 0 | P14: =SUM(D14:O14) -> 0
C15: Connecteam | D15: 0 | E15: 0 | F15: 0 | G15: 0 | H15: 0 | I15: 0 | J15: 0 | K15: 0 | L15: 0 | M15: 0 | N15: 0 | O15: 0 | P15: =SUM(D15:O15) -> 0
C16: Food and drinks | D16: 0 | E16: 0 | F16: 0 | G16: 0 | H16: 0 | I16: 0 | J16: 0 | K16: 0 | L16: 0 | M16: 0 | N16: 0 | O16: 0 | P16: =SUM(D16:O16) -> 0
C17: Gaji Hari parttimer | D17: 0 | E17: 0 | F17: 0 | G17: 0 | H17: 0 | I17: 0 | J17: 0 | K17: 0 | L17: 0 | M17: 0 | N17: 0 | O17: 0 | P17: =SUM(D17:O17) -> 0
C18: Maintenance and Repair Mesin | D18: 0 | E18: 0 | F18: 0 | G18: 0 | H18: 0 | I18: 0 | J18: 0 | K18: 0 | L18: 0 | M18: 0 | N18: 0 | O18: 0 | P18: =SUM(D18:O18) -> 0
C19: Others | D19: 0 | E19: 0 | F19: 0 | G19: 0 | H19: 0 | I19: 0 | J19: 0 | K19: 0 | L19: 0 | M19: 0 | N19: 0 | O19: 0 | P19: =SUM(D19:O19) -> 0
C20: Bonus | D20: 0 | E20: 0 | F20: 0 | G20: 0 | H20: 0 | I20: 0 | J20: 0 | K20: 0 | L20: 0 | M20: 0 | N20: 0 | O20: 0 | P20: =SUM(D20:O20) -> 0
C21: SPK | D21: 0 | E21: 0 | F21: 0 | G21: 0 | H21: 0 | I21: 0 | J21: 0 | K21: 0 | L21: 0 | M21: 0 | N21: 0 | O21: 0 | P21: =SUM(D21:O21) -> 0
C22: Salary | D22: 0 | E22: 0 | F22: 0 | G22: 0 | H22: 0 | I22: 0 | J22: 0 | K22: 0 | L22: 0 | M22: 0 | N22: 0 | O22: 0 | P22: =SUM(D22:O22) -> 0
